[2025-06-21T08:55:58.908+0000] {local_task_job_runner.py:120} INFO - ::group::Pre task execution logs
[2025-06-21T08:55:58.922+0000] {taskinstance.py:2076} INFO - Dependencies all met for dep_context=non-requeueable deps ti=<TaskInstance: twitter_etl_dag.extract_tweets manual__2025-06-21T08:50:55.862805+00:00 [queued]>
[2025-06-21T08:55:58.926+0000] {taskinstance.py:2076} INFO - Dependencies all met for dep_context=requeueable deps ti=<TaskInstance: twitter_etl_dag.extract_tweets manual__2025-06-21T08:50:55.862805+00:00 [queued]>
[2025-06-21T08:55:58.926+0000] {taskinstance.py:2306} INFO - Starting attempt 2 of 6
[2025-06-21T08:55:58.932+0000] {taskinstance.py:2330} INFO - Executing <Task(PythonOperator): extract_tweets> on 2025-06-21 08:50:55.862805+00:00
[2025-06-21T08:55:58.936+0000] {standard_task_runner.py:90} INFO - Running: ['***', 'tasks', 'run', 'twitter_etl_dag', 'extract_tweets', 'manual__2025-06-21T08:50:55.862805+00:00', '--job-id', '13', '--raw', '--subdir', 'DAGS_FOLDER/twitter_etl_dag.py', '--cfg-path', '/tmp/tmpnc7uf7s3']
[2025-06-21T08:55:58.938+0000] {standard_task_runner.py:91} INFO - Job 13: Subtask extract_tweets
[2025-06-21T08:55:58.937+0000] {logging_mixin.py:188} WARNING - /home/***/.local/lib/python3.12/site-packages/***/task/task_runner/standard_task_runner.py:61 DeprecationWarning: This process (pid=241) is multi-threaded, use of fork() may lead to deadlocks in the child.
[2025-06-21T08:55:58.939+0000] {standard_task_runner.py:63} INFO - Started process 242 to run task
[2025-06-21T08:55:58.961+0000] {task_command.py:426} INFO - Running <TaskInstance: twitter_etl_dag.extract_tweets manual__2025-06-21T08:50:55.862805+00:00 [running]> on host cbeabd6be8a4
[2025-06-21T08:55:58.998+0000] {taskinstance.py:2648} INFO - Exporting env vars: AIRFLOW_CTX_DAG_OWNER='***' AIRFLOW_CTX_DAG_ID='twitter_etl_dag' AIRFLOW_CTX_TASK_ID='extract_tweets' AIRFLOW_CTX_EXECUTION_DATE='2025-06-21T08:50:55.862805+00:00' AIRFLOW_CTX_TRY_NUMBER='2' AIRFLOW_CTX_DAG_RUN_ID='manual__2025-06-21T08:50:55.862805+00:00'
[2025-06-21T08:55:58.998+0000] {taskinstance.py:430} INFO - ::endgroup::
[2025-06-21T08:55:59.433+0000] {taskinstance.py:441} INFO - ::group::Post task execution logs
[2025-06-21T08:55:59.434+0000] {taskinstance.py:2905} ERROR - Task failed with exception
Traceback (most recent call last):
  File "/home/airflow/.local/lib/python3.12/site-packages/airflow/models/taskinstance.py", line 465, in _execute_task
    result = _execute_callable(context=context, **execute_callable_kwargs)
             ^^^^^^^^^^^^^^^^^^^^^^^^^^^^^^^^^^^^^^^^^^^^^^^^^^^^^^^^^^^^^
  File "/home/airflow/.local/lib/python3.12/site-packages/airflow/models/taskinstance.py", line 432, in _execute_callable
    return execute_callable(context=context, **execute_callable_kwargs)
           ^^^^^^^^^^^^^^^^^^^^^^^^^^^^^^^^^^^^^^^^^^^^^^^^^^^^^^^^^^^^
  File "/home/airflow/.local/lib/python3.12/site-packages/airflow/models/baseoperator.py", line 400, in wrapper
    return func(self, *args, **kwargs)
           ^^^^^^^^^^^^^^^^^^^^^^^^^^^
  File "/home/airflow/.local/lib/python3.12/site-packages/airflow/operators/python.py", line 235, in execute
    return_value = self.execute_callable()
                   ^^^^^^^^^^^^^^^^^^^^^^^
  File "/home/airflow/.local/lib/python3.12/site-packages/airflow/operators/python.py", line 252, in execute_callable
    return self.python_callable(*self.op_args, **self.op_kwargs)
           ^^^^^^^^^^^^^^^^^^^^^^^^^^^^^^^^^^^^^^^^^^^^^^^^^^^^^
  File "/opt/airflow/dags/twitter_etl_dag.py", line 43, in extract_tweets
    user = client.get_user(username='elonmusk')
           ^^^^^^^^^^^^^^^^^^^^^^^^^^^^^^^^^^^^
  File "/home/airflow/.local/lib/python3.12/site-packages/tweepy/client.py", line 2359, in get_user
    return self._make_request(
           ^^^^^^^^^^^^^^^^^^^
  File "/home/airflow/.local/lib/python3.12/site-packages/tweepy/client.py", line 129, in _make_request
    response = self.request(method, route, params=request_params,
               ^^^^^^^^^^^^^^^^^^^^^^^^^^^^^^^^^^^^^^^^^^^^^^^^^^
  File "/home/airflow/.local/lib/python3.12/site-packages/tweepy/client.py", line 115, in request
    raise TooManyRequests(response)
tweepy.errors.TooManyRequests: 429 Too Many Requests
Too Many Requests
[2025-06-21T08:55:59.442+0000] {taskinstance.py:1206} INFO - Marking task as UP_FOR_RETRY. dag_id=twitter_etl_dag, task_id=extract_tweets, run_id=manual__2025-06-21T08:50:55.862805+00:00, execution_date=20250621T085055, start_date=20250621T085558, end_date=20250621T085559
[2025-06-21T08:55:59.450+0000] {standard_task_runner.py:110} ERROR - Failed to execute job 13 for task extract_tweets (429 Too Many Requests
Too Many Requests; 242)
[2025-06-21T08:55:59.492+0000] {local_task_job_runner.py:240} INFO - Task exited with return code 1
[2025-06-21T08:55:59.508+0000] {taskinstance.py:3498} INFO - 0 downstream tasks scheduled from follow-on schedule check
[2025-06-21T08:55:59.509+0000] {local_task_job_runner.py:222} INFO - ::endgroup::
