[2025-06-20T08:28:35.374+0000] {local_task_job_runner.py:120} INFO - ::group::Pre task execution logs
[2025-06-20T08:28:35.394+0000] {taskinstance.py:2076} INFO - Dependencies all met for dep_context=non-requeueable deps ti=<TaskInstance: twitter_etl_dag.extract_tweets manual__2025-06-20T08:28:35.001099+00:00 [queued]>
[2025-06-20T08:28:35.399+0000] {taskinstance.py:2076} INFO - Dependencies all met for dep_context=requeueable deps ti=<TaskInstance: twitter_etl_dag.extract_tweets manual__2025-06-20T08:28:35.001099+00:00 [queued]>
[2025-06-20T08:28:35.400+0000] {taskinstance.py:2306} INFO - Starting attempt 1 of 6
[2025-06-20T08:28:35.406+0000] {taskinstance.py:2330} INFO - Executing <Task(PythonOperator): extract_tweets> on 2025-06-20 08:28:35.001099+00:00
[2025-06-20T08:28:35.413+0000] {standard_task_runner.py:90} INFO - Running: ['***', 'tasks', 'run', 'twitter_etl_dag', 'extract_tweets', 'manual__2025-06-20T08:28:35.001099+00:00', '--job-id', '15', '--raw', '--subdir', 'DAGS_FOLDER/twitter_etl_dag.py', '--cfg-path', '/tmp/tmp63m25w8n']
[2025-06-20T08:28:35.414+0000] {logging_mixin.py:188} WARNING - /home/***/.local/lib/python3.12/site-packages/***/task/task_runner/standard_task_runner.py:61 DeprecationWarning: This process (pid=181) is multi-threaded, use of fork() may lead to deadlocks in the child.
[2025-06-20T08:28:35.415+0000] {standard_task_runner.py:91} INFO - Job 15: Subtask extract_tweets
[2025-06-20T08:28:35.415+0000] {standard_task_runner.py:63} INFO - Started process 184 to run task
[2025-06-20T08:28:35.442+0000] {task_command.py:426} INFO - Running <TaskInstance: twitter_etl_dag.extract_tweets manual__2025-06-20T08:28:35.001099+00:00 [running]> on host 931f0b327f52
[2025-06-20T08:28:35.482+0000] {taskinstance.py:2648} INFO - Exporting env vars: AIRFLOW_CTX_DAG_OWNER='***' AIRFLOW_CTX_DAG_ID='twitter_etl_dag' AIRFLOW_CTX_TASK_ID='extract_tweets' AIRFLOW_CTX_EXECUTION_DATE='2025-06-20T08:28:35.001099+00:00' AIRFLOW_CTX_TRY_NUMBER='1' AIRFLOW_CTX_DAG_RUN_ID='manual__2025-06-20T08:28:35.001099+00:00'
[2025-06-20T08:28:35.483+0000] {taskinstance.py:430} INFO - ::endgroup::
[2025-06-20T08:28:35.892+0000] {taskinstance.py:441} INFO - ::group::Post task execution logs
[2025-06-20T08:28:35.892+0000] {taskinstance.py:2905} ERROR - Task failed with exception
Traceback (most recent call last):
  File "/home/airflow/.local/lib/python3.12/site-packages/airflow/models/taskinstance.py", line 465, in _execute_task
    result = _execute_callable(context=context, **execute_callable_kwargs)
             ^^^^^^^^^^^^^^^^^^^^^^^^^^^^^^^^^^^^^^^^^^^^^^^^^^^^^^^^^^^^^
  File "/home/airflow/.local/lib/python3.12/site-packages/airflow/models/taskinstance.py", line 432, in _execute_callable
    return execute_callable(context=context, **execute_callable_kwargs)
           ^^^^^^^^^^^^^^^^^^^^^^^^^^^^^^^^^^^^^^^^^^^^^^^^^^^^^^^^^^^^
  File "/home/airflow/.local/lib/python3.12/site-packages/airflow/models/baseoperator.py", line 400, in wrapper
    return func(self, *args, **kwargs)
           ^^^^^^^^^^^^^^^^^^^^^^^^^^^
  File "/home/airflow/.local/lib/python3.12/site-packages/airflow/operators/python.py", line 235, in execute
    return_value = self.execute_callable()
                   ^^^^^^^^^^^^^^^^^^^^^^^
  File "/home/airflow/.local/lib/python3.12/site-packages/airflow/operators/python.py", line 252, in execute_callable
    return self.python_callable(*self.op_args, **self.op_kwargs)
           ^^^^^^^^^^^^^^^^^^^^^^^^^^^^^^^^^^^^^^^^^^^^^^^^^^^^^
  File "/opt/airflow/dags/twitter_etl_dag.py", line 36, in extract_tweets
    user = client.get_user(username='elonmusk')
           ^^^^^^^^^^^^^^^^^^^^^^^^^^^^^^^^^^^^
  File "/home/airflow/.local/lib/python3.12/site-packages/tweepy/client.py", line 2359, in get_user
    return self._make_request(
           ^^^^^^^^^^^^^^^^^^^
  File "/home/airflow/.local/lib/python3.12/site-packages/tweepy/client.py", line 129, in _make_request
    response = self.request(method, route, params=request_params,
               ^^^^^^^^^^^^^^^^^^^^^^^^^^^^^^^^^^^^^^^^^^^^^^^^^^
  File "/home/airflow/.local/lib/python3.12/site-packages/tweepy/client.py", line 115, in request
    raise TooManyRequests(response)
tweepy.errors.TooManyRequests: 429 Too Many Requests
Too Many Requests
[2025-06-20T08:28:35.898+0000] {taskinstance.py:1206} INFO - Marking task as UP_FOR_RETRY. dag_id=twitter_etl_dag, task_id=extract_tweets, run_id=manual__2025-06-20T08:28:35.001099+00:00, execution_date=20250620T082835, start_date=20250620T082835, end_date=20250620T082835
[2025-06-20T08:28:35.906+0000] {standard_task_runner.py:110} ERROR - Failed to execute job 15 for task extract_tweets (429 Too Many Requests
Too Many Requests; 184)
[2025-06-20T08:28:35.937+0000] {local_task_job_runner.py:240} INFO - Task exited with return code 1
[2025-06-20T08:28:35.952+0000] {taskinstance.py:3498} INFO - 0 downstream tasks scheduled from follow-on schedule check
[2025-06-20T08:28:35.954+0000] {local_task_job_runner.py:222} INFO - ::endgroup::
